<!-- description of rockie's kinematics -->
<!-- note that all dimensions are in meters -->
<robot name="rockie">
  <!-- lower, back, right, corner of the frame -->
  <link name="corner">
  </link>

  <!-- the center of rotation for the robot at the height of the bottom of the frame -->
  <link name="base_link">
  </link>

  <joint name="corner_to_base_link" type="fixed">
    <parent link="base_link"/>
    <child link="corner"/>

    <!-- need actual values -->
    <origin xyz="-0.4572 -0.3048 0"/>
  </joint>

  <link name="arm_revolute">
  </link>

  <joint name="corner_to_arm_revolute" type="revolute">
    <parent link="corner"/>
    <child link="arm_revolute"/>

    <!-- need actual limits -->
    <limit lower="0" upper="3.14159" effort="1.0" velocity="1.0"/>

    <!-- bottom of arm body at center of rotation -->
    <origin xyz="0.942975 0.098425 0.73025"/>

    <axis xyz="0 0 1"/>
  </joint>

  <link name="arm_prismatic">
  </link>

  <joint name="arm_revolute_to_arm_prismatic" type="prismatic">
    <parent link="arm_revolute"/>
    <child link="arm_prismatic"/>

    <limit lower="0" upper="0.542925" effort="1.0" velocity="1.0"/>

    <!-- center of sliding 8020 at same height as origin of revolute -->
    <origin xyz="0.3302 0 0"/>

    <axis xyz="0 0 1"/>
  </joint>

  <link name="gripper">
  </link>

  <joint name="arm_prismatic_to_gripper" type="revolute">
    <parent link="arm_prismatic"/>
    <child link="gripper"/>

    <!-- need actual limits -->
    <limit lower="-1.57" upper="1.57" effort="1.0" velocity="1.0"/>

    <!-- end of gripper -->
    <origin xyz="0 0.053974999999999995 -0.8191499999999999"/>

    <axis xyz="0 0 1"/>
  </joint>

  <!-- adding the sample tray will be necessary sometime -->

  <!--
  rotated frame of the stereo camera platform at the axis of rotation on the
  right side of the robot
  -->
  <link name="stereo_camera_platform">
  </link>

  
  <joint name="corner_to_stereo_camera_platform" type="fixed">
    <parent link="corner"/>
    <child link="stereo_camera_platform"/>
    <!-- 30 degree rotation of the stereo camera platform -->
    <origin xyz="0.9017 0 0.6985" rpy="0.0 0.2205 0.0"/>
  </joint>

  <!--
  camera origin
  -->
  <link name="stereo_camera">
  </link>

  <joint name="stereo_camera_platform_to_stereo_camera" type="fixed">
    <parent link="stereo_camera_platform"/>
    <child link="stereo_camera"/>
    <!-- rotation because of different coordinate system for cameras -->
    <origin xyz="0.0333375 0.5651499999999999 0.038099999999999995" rpy="-1.5707963267948966 0 -1.5707963267948966"/>
  </joint>

  <joint name="/left_camera_joint" type="fixed">
     <origin rpy="-0.105078 -0.818555 -0.100929" xyz="-0.163691 0.12499 -0.00243303"/>
     <parent link="stereo_camera"/>
     <child link="/left_camera"/>
  </joint>
  <link name="/left_camera" type="camera"/>
  <!-- added after running camera_pose_calibration -->
  <joint name="/right_camera_joint" type="fixed">
     <origin rpy="-0.279391 0.381873 -0.0456388" xyz="0.714194 0.0981112 0.0825147"/>
     <parent link="stereo_camera"/>
     <child link="/right_camera"/>
  </joint>
  <link name="/right_camera" type="camera"/>
</robot>
